<?xml version="1.0" encoding="utf-8"?>
<!-- =================================================================================== -->
<!-- |    This document was autogenerated by xacro from arm.xacro                      | -->
<!-- |    EDITING THIS FILE BY HAND IS NOT RECOMMENDED                                 | -->
<!-- =================================================================================== -->
<robot name="z1">
  <link name="base_link"/>
  <link name="link01"/>
  <link name="link02"/>
  <link name="link03"/>
  <link name="link04"/>
  <link name="link05"/>
  <link name="link06"/>
  <link name="link07"/>
  <joint name="joint1" type="revolute">
    <origin rpy="0 0 0" xyz="0 0 0.065"/>
    <parent link="base_link"/>
    <child link="link01"/>
    <axis xyz="0 0 1"/>
    <limit effort="30.0" lower="-2.61799387799" upper="2.61799387799" velocity="10"/>
  </joint>
  <joint name="joint2" type="revolute">
    <origin rpy="0 0 0" xyz="0 0 0.04"/>
    <parent link="link01"/>
    <child link="link02"/>
    <axis xyz="0 1 0"/>
    <limit effort="30.0" lower="0.0" upper="3.14159265359" velocity="10"/>
  </joint>
  <joint name="joint3" type="revolute">
    <origin rpy="0 0 0" xyz="-0.35 0 0"/>
    <parent link="link02"/>
    <child link="link03"/>
    <axis xyz="0 1 0"/>
    <limit effort="30.0" lower="-4.78220215046" upper="0.0" velocity="10"/>
  </joint>
  <joint name="joint4" type="revolute">
    <origin rpy="0 0 0" xyz="0.218 0 0.057"/>
    <parent link="link03"/>
    <child link="link04"/>
    <axis xyz="0 1 0"/>
    <limit effort="30.0" lower="-1.74532925199" upper="1.57079632679" velocity="10"/>
  </joint>
  <joint name="joint5" type="revolute">
    <origin rpy="0 0 0" xyz="0.072 0.0 0.0"/>
    <parent link="link04"/>
    <child link="link05"/>
    <axis xyz="0 0 1"/>
    <limit effort="30.0" lower="-1.72787595947" upper="1.72787595947" velocity="10"/>
  </joint>
  <joint name="joint6" type="revolute">
    <origin rpy="0 0 0" xyz="0.1 0.0 0.0"/>
    <parent link="link05"/>
    <child link="link06"/>
    <axis xyz="1 0 0"/>
    <limit effort="30.0" lower="-2.79252680319" upper="2.79252680319" velocity="10"/>
  </joint>
  <joint name="joint7" type="fixed">
    <origin rpy="0 0 0" xyz="0.0 0.0 0.0"/>
    <parent link="link06"/>
    <child link="link07"/>
  </joint>
</robot>
